[2021-12-16T16:54:11Z] DEBUG    - Logging set up successfully
[2021-12-16T16:54:11Z] DEBUG    - Running generate: Namespace(version=False, subparser_name='generate', command=<function generate at 0x11ffae280>, verbose=0)
[2021-12-16T16:54:11Z] DEBUG    - Root directory: /Users/brianter/Documents/repo/github-repo/dop304/java-example/step-2
[2021-12-16T16:54:11Z] DEBUG    - Loading project file '/Users/brianter/Documents/repo/github-repo/dop304/java-example/step-2/.rpdk-config'
[2021-12-16T16:54:11Z] DEBUG    - Project file /Users/brianter/Documents/repo/github-repo/dop304/java-example/step-2/.rpdk-config not found. Have you run 'init' or in a wrong directory?
Traceback (most recent call last):
  File "/Users/brianter/Documents/repo/github-repo/dop304/env/lib/python3.9/site-packages/rpdk/core/project.py", line 442, in load
    self.load_settings()
  File "/Users/brianter/Documents/repo/github-repo/dop304/env/lib/python3.9/site-packages/rpdk/core/project.py", line 195, in load_settings
    with self.settings_path.open("r", encoding="utf-8") as f:
  File "/usr/local/Cellar/python@3.9/3.9.7_1/Frameworks/Python.framework/Versions/3.9/lib/python3.9/pathlib.py", line 1252, in open
    return io.open(self, mode, buffering, encoding, errors, newline,
  File "/usr/local/Cellar/python@3.9/3.9.7_1/Frameworks/Python.framework/Versions/3.9/lib/python3.9/pathlib.py", line 1120, in _opener
    return self._accessor.open(self, flags, mode)
FileNotFoundError: [Errno 2] No such file or directory: '/Users/brianter/Documents/repo/github-repo/dop304/java-example/step-2/.rpdk-config'
[2021-12-16T16:54:11Z] DEBUG    - Caught exit recommendation
Traceback (most recent call last):
  File "/Users/brianter/Documents/repo/github-repo/dop304/env/lib/python3.9/site-packages/rpdk/core/project.py", line 442, in load
    self.load_settings()
  File "/Users/brianter/Documents/repo/github-repo/dop304/env/lib/python3.9/site-packages/rpdk/core/project.py", line 195, in load_settings
    with self.settings_path.open("r", encoding="utf-8") as f:
  File "/usr/local/Cellar/python@3.9/3.9.7_1/Frameworks/Python.framework/Versions/3.9/lib/python3.9/pathlib.py", line 1252, in open
    return io.open(self, mode, buffering, encoding, errors, newline,
  File "/usr/local/Cellar/python@3.9/3.9.7_1/Frameworks/Python.framework/Versions/3.9/lib/python3.9/pathlib.py", line 1120, in _opener
    return self._accessor.open(self, flags, mode)
FileNotFoundError: [Errno 2] No such file or directory: '/Users/brianter/Documents/repo/github-repo/dop304/java-example/step-2/.rpdk-config'

The above exception was the direct cause of the following exception:

Traceback (most recent call last):
  File "/Users/brianter/Documents/repo/github-repo/dop304/env/lib/python3.9/site-packages/rpdk/core/cli.py", line 100, in main
    args.command(args)
  File "/Users/brianter/Documents/repo/github-repo/dop304/env/lib/python3.9/site-packages/rpdk/core/generate.py", line 14, in generate
    project.load()
  File "/Users/brianter/Documents/repo/github-repo/dop304/env/lib/python3.9/site-packages/rpdk/core/project.py", line 444, in load
    self._raise_invalid_project(
  File "/Users/brianter/Documents/repo/github-repo/dop304/env/lib/python3.9/site-packages/rpdk/core/project.py", line 190, in _raise_invalid_project
    raise InvalidProjectError(msg) from e
rpdk.core.exceptions.InvalidProjectError: Project file /Users/brianter/Documents/repo/github-repo/dop304/java-example/step-2/.rpdk-config not found. Have you run 'init' or in a wrong directory?
[2021-12-16T16:54:11Z] CRITICAL - Project file /Users/brianter/Documents/repo/github-repo/dop304/java-example/step-2/.rpdk-config not found. Have you run 'init' or in a wrong directory?
